<?xml version='1.0'?>
<sdf version='1.7'>
  <model name='grabber#5'>
    <link name='link_0'>
      <inertial>
        <mass>0.112</mass>
        <inertia>
          <ixx>4.373e-05</ixx>
          <ixy>8e-08</ixy>
          <ixz>2.3e-07</ixz>
          <iyy>0.0001193</iyy>
          <iyz>7e-08</iyz>
          <izz>0.0001195</izz>
        </inertia>
        <pose>0 0 0 0 -0 0</pose>
      </inertial>
      <pose>-0.008375 -0.009212 0.06 0 -0 0</pose>
      <gravity>1</gravity>
      <self_collide>1</self_collide>
      <kinematic>0</kinematic>
      <enable_wind>0</enable_wind>
      <visual name='visual'>
        <pose>0 0 0 0 -0 0</pose>
        <geometry>
          <mesh>
            <uri>/home/george/GEE301/Grabber stls/final stls/cylinder.stl</uri>
            <scale>1 1 1</scale>
          </mesh>
        </geometry>
        <material>
          <lighting>1</lighting>
          <script>
            <uri>file://media/materials/scripts/gazebo.material</uri>
            <name>Gazebo/Grey</name>
          </script>
          <shader type='pixel'>
            <normal_map>__default__</normal_map>
          </shader>
          <ambient>0.3 0.3 0.3 1</ambient>
          <diffuse>0.7 0.7 0.7 1</diffuse>
          <specular>0.01 0.01 0.01 1</specular>
          <emissive>0 0 0 1</emissive>
        </material>
        <transparency>0</transparency>
        <cast_shadows>1</cast_shadows>
      </visual>
      <collision name='collision'>
        <laser_retro>0</laser_retro>
        <max_contacts>10</max_contacts>
        <pose>0 0 0 0 -0 0</pose>
        <geometry>
          <mesh>
            <uri>/home/george/GEE301/Grabber stls/final stls/cylinder_collisional.stl</uri>
            <scale>1 1 1</scale>
          </mesh>
        </geometry>
        <surface>
          <friction>
            <ode>
              <mu>1</mu>
              <mu2>1</mu2>
              <fdir1>0 0 0</fdir1>
              <slip1>0</slip1>
              <slip2>0</slip2>
            </ode>
            <torsional>
              <coefficient>1</coefficient>
              <patch_radius>0</patch_radius>
              <surface_radius>0</surface_radius>
              <use_patch_radius>1</use_patch_radius>
              <ode>
                <slip>0</slip>
              </ode>
            </torsional>
          </friction>
          <bounce>
            <restitution_coefficient>0</restitution_coefficient>
            <threshold>1e+06</threshold>
          </bounce>
          <contact>
            <collide_without_contact>0</collide_without_contact>
            <collide_without_contact_bitmask>1</collide_without_contact_bitmask>
            <collide_bitmask>1</collide_bitmask>
            <ode>
              <soft_cfm>0</soft_cfm>
              <soft_erp>0.2</soft_erp>
              <kp>1e+13</kp>
              <kd>1</kd>
              <max_vel>0.01</max_vel>
              <min_depth>0</min_depth>
            </ode>
            <bullet>
              <split_impulse>1</split_impulse>
              <split_impulse_penetration_threshold>-0.01</split_impulse_penetration_threshold>
              <soft_cfm>0</soft_cfm>
              <soft_erp>0.2</soft_erp>
              <kp>1e+13</kp>
              <kd>1</kd>
            </bullet>
          </contact>
        </surface>
      </collision>
    </link>
    <link name='link_1'>
      <inertial>
        <mass>0.006</mass>
        <inertia>
          <ixx>4.524e-05</ixx>
          <ixy>1.584e-05</ixy>
          <ixz>1.258e-05</ixz>
          <iyy>2.655e-05</iyy>
          <iyz>2.161e-05</iyz>
          <izz>3.748e-05</izz>
        </inertia>
        <pose>0 0 0 0 -0 0</pose>
      </inertial>
      <pose>0.042125 0.011288 0.06 3.14159 1.57079 3.14159</pose>
      <gravity>1</gravity>
      <self_collide>0</self_collide>
      <kinematic>0</kinematic>
      <enable_wind>0</enable_wind>
      <visual name='visual'>
        <pose>0 0 0 0 -0 0</pose>
        <geometry>
          <mesh>
            <uri>/home/george/GEE301/Grabber stls/final stls/long_arm.stl</uri>
            <scale>1 1 1</scale>
          </mesh>
        </geometry>
        <material>
          <lighting>1</lighting>
          <script>
            <uri>file://media/materials/scripts/gazebo.material</uri>
            <name>Gazebo/Grey</name>
          </script>
          <shader type='pixel'>
            <normal_map>__default__</normal_map>
          </shader>
          <ambient>0.3 0.3 0.3 1</ambient>
          <diffuse>0.7 0.7 0.7 1</diffuse>
          <specular>0.01 0.01 0.01 1</specular>
          <emissive>0 0 0 1</emissive>
        </material>
        <transparency>0</transparency>
        <cast_shadows>1</cast_shadows>
      </visual>
    </link>
    <link name='link_10'>
      <inertial>
        <mass>0.0048</mass>
        <inertia>
          <ixx>0.0004447</ixx>
          <ixy>2.355e-05</ixy>
          <ixz>0.0001345</ixz>
          <iyy>0.0004994</iyy>
          <iyz>6.34e-05</iyz>
          <izz>7.824e-05</izz>
        </inertia>
        <pose>0 0 0 0 -0 0</pose>
      </inertial>
      <pose>0.04165 -0.03445 0.0163 -1.0472 -0 -3.14159</pose>
      <gravity>1</gravity>
      <self_collide>1</self_collide>
      <kinematic>0</kinematic>
      <enable_wind>0</enable_wind>
      <visual name='visual'>
        <pose>0 0 0 0 -0 0</pose>
        <geometry>
          <mesh>
            <uri>/home/george/GEE301/Grabber stls/final stls/outer_arm.stl</uri>
            <scale>1 1 1</scale>
          </mesh>
        </geometry>
        <material>
          <lighting>1</lighting>
          <script>
            <uri>file://media/materials/scripts/gazebo.material</uri>
            <name>Gazebo/Grey</name>
          </script>
          <shader type='pixel'>
            <normal_map>__default__</normal_map>
          </shader>
          <ambient>0.3 0.3 0.3 1</ambient>
          <diffuse>0.7 0.7 0.7 1</diffuse>
          <specular>0.01 0.01 0.01 1</specular>
          <emissive>0 0 0 1</emissive>
        </material>
        <transparency>0</transparency>
        <cast_shadows>1</cast_shadows>
      </visual>
      <collision name='collision'>
        <laser_retro>0</laser_retro>
        <max_contacts>10</max_contacts>
        <pose>0 0 0 0 -0 0</pose>
        <geometry>
          <mesh>
            <uri>/home/george/GEE301/Grabber stls/final stls/outer_arm_collisional.stl</uri>
            <scale>1 1 1</scale>
          </mesh>
        </geometry>
        <surface>
          <friction>
            <ode>
              <mu>1</mu>
              <mu2>1</mu2>
              <fdir1>0 0 0</fdir1>
              <slip1>0</slip1>
              <slip2>0</slip2>
            </ode>
            <torsional>
              <coefficient>1</coefficient>
              <patch_radius>0</patch_radius>
              <surface_radius>0</surface_radius>
              <use_patch_radius>1</use_patch_radius>
              <ode>
                <slip>0</slip>
              </ode>
            </torsional>
          </friction>
          <bounce>
            <restitution_coefficient>0</restitution_coefficient>
            <threshold>1e+06</threshold>
          </bounce>
          <contact>
            <collide_without_contact>0</collide_without_contact>
            <collide_without_contact_bitmask>1</collide_without_contact_bitmask>
            <collide_bitmask>1</collide_bitmask>
            <ode>
              <soft_cfm>0</soft_cfm>
              <soft_erp>0.2</soft_erp>
              <kp>1e+13</kp>
              <kd>1</kd>
              <max_vel>0.01</max_vel>
              <min_depth>0</min_depth>
            </ode>
            <bullet>
              <split_impulse>1</split_impulse>
              <split_impulse_penetration_threshold>-0.01</split_impulse_penetration_threshold>
              <soft_cfm>0</soft_cfm>
              <soft_erp>0.2</soft_erp>
              <kp>1e+13</kp>
              <kd>1</kd>
            </bullet>
          </contact>
        </surface>
      </collision>
    </link>
    <link name='link_2'>
      <inertial>
        <mass>0.004</mass>
        <inertia>
          <ixx>4.66e-06</ixx>
          <ixy>1.01e-06</ixy>
          <ixz>1.14e-06</ixz>
          <iyy>3.21e-06</iyy>
          <iyz>2.28e-06</iyz>
          <izz>2.56e-06</izz>
        </inertia>
        <pose>0 0 0 0 -0 0</pose>
      </inertial>
      <pose>-0.008375 0.011288 0.06 3.14159 1.57079 3.14159</pose>
      <gravity>1</gravity>
      <self_collide>0</self_collide>
      <kinematic>0</kinematic>
      <enable_wind>0</enable_wind>
      <visual name='visual'>
        <pose>0 0 0 0 -0 0</pose>
        <geometry>
          <mesh>
            <uri>/home/george/GEE301/Grabber stls/final stls/short_arm.stl</uri>
            <scale>1 1 1</scale>
          </mesh>
        </geometry>
        <material>
          <lighting>1</lighting>
          <script>
            <uri>file://media/materials/scripts/gazebo.material</uri>
            <name>Gazebo/Grey</name>
          </script>
          <shader type='pixel'>
            <normal_map>__default__</normal_map>
          </shader>
          <ambient>0.3 0.3 0.3 1</ambient>
          <diffuse>0.7 0.7 0.7 1</diffuse>
          <specular>0.01 0.01 0.01 1</specular>
          <emissive>0 0 0 1</emissive>
        </material>
        <transparency>0</transparency>
        <cast_shadows>1</cast_shadows>
      </visual>
    </link>
    <link name='link_3'>
      <inertial>
        <mass>0.048</mass>
        <inertia>
          <ixx>0.0004447</ixx>
          <ixy>2.355e-05</ixy>
          <ixz>0.0001345</ixz>
          <iyy>0.0004994</iyy>
          <iyz>6.34e-05</iyz>
          <izz>7.824e-05</izz>
        </inertia>
        <pose>0 0 0 0 -0 0</pose>
      </inertial>
      <pose>0.041958 0.041305 0.06 3.14159 1e-06 3.14159</pose>
      <gravity>1</gravity>
      <self_collide>1</self_collide>
      <kinematic>0</kinematic>
      <enable_wind>0</enable_wind>
      <visual name='visual'>
        <pose>0 0 0 0 -0 0</pose>
        <geometry>
          <mesh>
            <uri>/home/george/GEE301/Grabber stls/final stls/outer_arm.stl</uri>
            <scale>1 1 1</scale>
          </mesh>
        </geometry>
        <material>
          <lighting>1</lighting>
          <script>
            <uri>file://media/materials/scripts/gazebo.material</uri>
            <name>Gazebo/Grey</name>
          </script>
          <shader type='pixel'>
            <normal_map>__default__</normal_map>
          </shader>
          <ambient>0.3 0.3 0.3 1</ambient>
          <diffuse>0.7 0.7 0.7 1</diffuse>
          <specular>0.01 0.01 0.01 1</specular>
          <emissive>0 0 0 1</emissive>
        </material>
        <transparency>0</transparency>
        <cast_shadows>1</cast_shadows>
      </visual>
      <collision name='collision'>
        <laser_retro>0</laser_retro>
        <max_contacts>10</max_contacts>
        <pose>0 0 0 0 -0 0</pose>
        <geometry>
          <mesh>
            <uri>/home/george/GEE301/Grabber stls/final stls/outer_arm_collisional.stl</uri>
            <scale>1 1 1</scale>
          </mesh>
        </geometry>
        <surface>
          <friction>
            <ode>
              <mu>1</mu>
              <mu2>1</mu2>
              <fdir1>0 0 0</fdir1>
              <slip1>0</slip1>
              <slip2>0</slip2>
            </ode>
            <torsional>
              <coefficient>1</coefficient>
              <patch_radius>0</patch_radius>
              <surface_radius>0</surface_radius>
              <use_patch_radius>1</use_patch_radius>
              <ode>
                <slip>0</slip>
              </ode>
            </torsional>
          </friction>
          <bounce>
            <restitution_coefficient>0</restitution_coefficient>
            <threshold>1e+06</threshold>
          </bounce>
          <contact>
            <collide_without_contact>0</collide_without_contact>
            <collide_without_contact_bitmask>1</collide_without_contact_bitmask>
            <collide_bitmask>1</collide_bitmask>
            <ode>
              <soft_cfm>0</soft_cfm>
              <soft_erp>0.2</soft_erp>
              <kp>1e+13</kp>
              <kd>1</kd>
              <max_vel>0.01</max_vel>
              <min_depth>0</min_depth>
            </ode>
            <bullet>
              <split_impulse>1</split_impulse>
              <split_impulse_penetration_threshold>-0.01</split_impulse_penetration_threshold>
              <soft_cfm>0</soft_cfm>
              <soft_erp>0.2</soft_erp>
              <kp>1e+13</kp>
              <kd>1</kd>
            </bullet>
          </contact>
        </surface>
      </collision>
    </link>
    <link name='link_3_0'>
      <inertial>
        <mass>0.0007213</mass>
        <inertia>
          <ixx>3.434e-06</ixx>
          <ixy>1.162e-06</ixy>
          <ixz>1.415e-06</ixz>
          <iyy>3.035e-06</iyy>
          <iyz>1.679e-06</iyz>
          <izz>2.358e-06</izz>
        </inertia>
        <pose>0 0 0 0 -0 0</pose>
      </inertial>
      <pose>0.0448 -0.0035 0.06 1.5708 -0 0</pose>
      <gravity>1</gravity>
      <self_collide>0</self_collide>
      <kinematic>0</kinematic>
      <enable_wind>0</enable_wind>
      <visual name='visual'>
        <pose>0 0 0 0 -0 0</pose>
        <geometry>
          <mesh>
            <uri>/home/george/GEE301/Grabber stls/final stls/pin.stl</uri>
            <scale>1 1 1</scale>
          </mesh>
        </geometry>
        <material>
          <lighting>1</lighting>
          <script>
            <uri>file://media/materials/scripts/gazebo.material</uri>
            <name>Gazebo/Grey</name>
          </script>
          <shader type='pixel'>
            <normal_map>__default__</normal_map>
          </shader>
          <ambient>0.3 0.3 0.3 1</ambient>
          <diffuse>0.7 0.7 0.7 1</diffuse>
          <specular>0.01 0.01 0.01 1</specular>
          <emissive>0 0 0 1</emissive>
        </material>
        <transparency>0</transparency>
        <cast_shadows>1</cast_shadows>
      </visual>
    </link>
    <link name='link_5'>
      <inertial>
        <mass>0.006</mass>
        <inertia>
          <ixx>4.562e-05</ixx>
          <ixy>1.584e-05</ixy>
          <ixz>1.258e-05</ixz>
          <iyy>2.655e-05</iyy>
          <iyz>2.161e-05</iyz>
          <izz>3.748e-05</izz>
        </inertia>
        <pose>0 0 0 0 -0 0</pose>
      </inertial>
      <pose>0.0416 -0.0195 0.0778 1.5708 -0.523599 1.5708</pose>
      <gravity>1</gravity>
      <self_collide>0</self_collide>
      <kinematic>0</kinematic>
      <enable_wind>0</enable_wind>
      <visual name='visual'>
        <pose>0 0 0 0 -0 0</pose>
        <geometry>
          <mesh>
            <uri>/home/george/GEE301/Grabber stls/final stls/long_arm.stl</uri>
            <scale>1 1 1</scale>
          </mesh>
        </geometry>
        <material>
          <lighting>1</lighting>
          <script>
            <uri>file://media/materials/scripts/gazebo.material</uri>
            <name>Gazebo/Grey</name>
          </script>
          <shader type='pixel'>
            <normal_map>__default__</normal_map>
          </shader>
          <ambient>0.3 0.3 0.3 1</ambient>
          <diffuse>0.7 0.7 0.7 1</diffuse>
          <specular>0.01 0.01 0.01 1</specular>
          <emissive>0 0 0 1</emissive>
        </material>
        <transparency>0</transparency>
        <cast_shadows>1</cast_shadows>
      </visual>
    </link>
    <link name='link_6'>
      <inertial>
        <mass>0.004</mass>
        <inertia>
          <ixx>4.66e-06</ixx>
          <ixy>1.01e-06</ixy>
          <ixz>1.14e-06</ixz>
          <iyy>3.21e-06</iyy>
          <iyz>2.28e-06</iyz>
          <izz>2.56e-06</izz>
        </inertia>
        <pose>0 0 0 0 -0 0</pose>
      </inertial>
      <pose>-0.008375 -0.0195 0.0778 1.578 -0.523599 1.5708</pose>
      <gravity>1</gravity>
      <self_collide>0</self_collide>
      <kinematic>0</kinematic>
      <enable_wind>0</enable_wind>
      <visual name='visual'>
        <pose>0 0 0 0 -0 0</pose>
        <geometry>
          <mesh>
            <uri>/home/george/GEE301/Grabber stls/final stls/short_arm.stl</uri>
            <scale>1 1 1</scale>
          </mesh>
        </geometry>
        <material>
          <lighting>1</lighting>
          <script>
            <uri>file://media/materials/scripts/gazebo.material</uri>
            <name>Gazebo/Grey</name>
          </script>
          <shader type='pixel'>
            <normal_map>__default__</normal_map>
          </shader>
          <ambient>0.3 0.3 0.3 1</ambient>
          <diffuse>0.7 0.7 0.7 1</diffuse>
          <specular>0.01 0.01 0.01 1</specular>
          <emissive>0 0 0 1</emissive>
        </material>
        <transparency>0</transparency>
        <cast_shadows>1</cast_shadows>
      </visual>
    </link>
    <link name='link_7'>
      <inertial>
        <mass>0.048</mass>
        <inertia>
          <ixx>0.0004447</ixx>
          <ixy>2.355e-05</ixy>
          <ixz>0.0001345</ixz>
          <iyy>0.0004994</iyy>
          <iyz>6.34e-05</iyz>
          <izz>7.824e-05</izz>
        </inertia>
        <pose>0 0 0 0 -0 0</pose>
      </inertial>
      <pose>0.04165 -0.03445 0.1037 1.0472 0 -3.14159</pose>
      <gravity>1</gravity>
      <self_collide>1</self_collide>
      <kinematic>0</kinematic>
      <enable_wind>0</enable_wind>
      <visual name='visual'>
        <pose>0 0 0 0 -0 0</pose>
        <geometry>
          <mesh>
            <uri>/home/george/GEE301/Grabber stls/final stls/outer_arm.stl</uri>
            <scale>1 1 1</scale>
          </mesh>
        </geometry>
        <material>
          <lighting>1</lighting>
          <script>
            <uri>file://media/materials/scripts/gazebo.material</uri>
            <name>Gazebo/Grey</name>
          </script>
          <shader type='pixel'>
            <normal_map>__default__</normal_map>
          </shader>
          <ambient>0.3 0.3 0.3 1</ambient>
          <diffuse>0.7 0.7 0.7 1</diffuse>
          <specular>0.01 0.01 0.01 1</specular>
          <emissive>0 0 0 1</emissive>
        </material>
        <transparency>0</transparency>
        <cast_shadows>1</cast_shadows>
      </visual>
      <collision name='collision'>
        <laser_retro>0</laser_retro>
        <max_contacts>10</max_contacts>
        <pose>0 0 0 0 -0 0</pose>
        <geometry>
          <mesh>
            <uri>/home/george/GEE301/Grabber stls/final stls/outer_arm_collisional.stl</uri>
            <scale>1 1 1</scale>
          </mesh>
        </geometry>
        <surface>
          <friction>
            <ode>
              <mu>1</mu>
              <mu2>1</mu2>
              <fdir1>0 0 0</fdir1>
              <slip1>0</slip1>
              <slip2>0</slip2>
            </ode>
            <torsional>
              <coefficient>1</coefficient>
              <patch_radius>0</patch_radius>
              <surface_radius>0</surface_radius>
              <use_patch_radius>1</use_patch_radius>
              <ode>
                <slip>0</slip>
              </ode>
            </torsional>
          </friction>
          <bounce>
            <restitution_coefficient>0</restitution_coefficient>
            <threshold>1e+06</threshold>
          </bounce>
          <contact>
            <collide_without_contact>0</collide_without_contact>
            <collide_without_contact_bitmask>1</collide_without_contact_bitmask>
            <collide_bitmask>1</collide_bitmask>
            <ode>
              <soft_cfm>0</soft_cfm>
              <soft_erp>0.2</soft_erp>
              <kp>1e+13</kp>
              <kd>1</kd>
              <max_vel>0.01</max_vel>
              <min_depth>0</min_depth>
            </ode>
            <bullet>
              <split_impulse>1</split_impulse>
              <split_impulse_penetration_threshold>-0.01</split_impulse_penetration_threshold>
              <soft_cfm>0</soft_cfm>
              <soft_erp>0.2</soft_erp>
              <kp>1e+13</kp>
              <kd>1</kd>
            </bullet>
          </contact>
        </surface>
      </collision>
    </link>
    <link name='link_8'>
      <inertial>
        <mass>0.006</mass>
        <inertia>
          <ixx>4.562e-05</ixx>
          <ixy>1.584e-05</ixy>
          <ixz>1.258e-05</ixz>
          <iyy>2.655e-05</iyy>
          <iyz>2.161e-05</iyz>
          <izz>3.748e-05</izz>
        </inertia>
        <pose>0 0 0 0 -0 0</pose>
      </inertial>
      <pose>0.0416 -0.0195 0.0422 -1.5708 -0.523603 -1.5708</pose>
      <gravity>1</gravity>
      <self_collide>0</self_collide>
      <kinematic>0</kinematic>
      <enable_wind>0</enable_wind>
      <visual name='visual'>
        <pose>0 0 0 0 -0 0</pose>
        <geometry>
          <mesh>
            <uri>/home/george/GEE301/Grabber stls/final stls/long_arm.stl</uri>
            <scale>1 1 1</scale>
          </mesh>
        </geometry>
        <material>
          <lighting>1</lighting>
          <script>
            <uri>file://media/materials/scripts/gazebo.material</uri>
            <name>Gazebo/Grey</name>
          </script>
          <shader type='pixel'>
            <normal_map>__default__</normal_map>
          </shader>
          <ambient>0.3 0.3 0.3 1</ambient>
          <diffuse>0.7 0.7 0.7 1</diffuse>
          <specular>0.01 0.01 0.01 1</specular>
          <emissive>0 0 0 1</emissive>
        </material>
        <transparency>0</transparency>
        <cast_shadows>1</cast_shadows>
      </visual>
      <collision name='collision'>
        <laser_retro>0</laser_retro>
        <max_contacts>10</max_contacts>
        <pose>0 0 0 0 -0 0</pose>
        <geometry>
          <mesh>
            <uri>/home/george/GEE301/Grabber stls/final stls/long_arm.stl</uri>
            <scale>1 1 1</scale>
          </mesh>
        </geometry>
        <surface>
          <friction>
            <ode>
              <mu>1</mu>
              <mu2>1</mu2>
              <fdir1>0 0 0</fdir1>
              <slip1>0</slip1>
              <slip2>0</slip2>
            </ode>
            <torsional>
              <coefficient>1</coefficient>
              <patch_radius>0</patch_radius>
              <surface_radius>0</surface_radius>
              <use_patch_radius>1</use_patch_radius>
              <ode>
                <slip>0</slip>
              </ode>
            </torsional>
          </friction>
          <bounce>
            <restitution_coefficient>0</restitution_coefficient>
            <threshold>1e+06</threshold>
          </bounce>
          <contact>
            <collide_without_contact>0</collide_without_contact>
            <collide_without_contact_bitmask>1</collide_without_contact_bitmask>
            <collide_bitmask>1</collide_bitmask>
            <ode>
              <soft_cfm>0</soft_cfm>
              <soft_erp>0.2</soft_erp>
              <kp>1e+13</kp>
              <kd>1</kd>
              <max_vel>0.01</max_vel>
              <min_depth>0</min_depth>
            </ode>
            <bullet>
              <split_impulse>1</split_impulse>
              <split_impulse_penetration_threshold>-0.01</split_impulse_penetration_threshold>
              <soft_cfm>0</soft_cfm>
              <soft_erp>0.2</soft_erp>
              <kp>1e+13</kp>
              <kd>1</kd>
            </bullet>
          </contact>
        </surface>
      </collision>
    </link>
    <link name='link_9'>
      <inertial>
        <mass>0.004</mass>
        <inertia>
          <ixx>4.66e-06</ixx>
          <ixy>1.01e-06</ixy>
          <ixz>1.14e-06</ixz>
          <iyy>3.21e-06</iyy>
          <iyz>2.28e-06</iyz>
          <izz>2.56e-06</izz>
        </inertia>
        <pose>0 0 0 0 -0 0</pose>
      </inertial>
      <pose>-0.008375 -0.0195 0.0422 -1.5708 -0.523603 -1.5708</pose>
      <gravity>1</gravity>
      <self_collide>0</self_collide>
      <kinematic>0</kinematic>
      <enable_wind>0</enable_wind>
      <visual name='visual'>
        <pose>0 0 0 0 -0 0</pose>
        <geometry>
          <mesh>
            <uri>/home/george/GEE301/Grabber stls/final stls/short_arm.stl</uri>
            <scale>1 1 1</scale>
          </mesh>
        </geometry>
        <material>
          <lighting>1</lighting>
          <script>
            <uri>file://media/materials/scripts/gazebo.material</uri>
            <name>Gazebo/Grey</name>
          </script>
          <shader type='pixel'>
            <normal_map>__default__</normal_map>
          </shader>
          <ambient>0.3 0.3 0.3 1</ambient>
          <diffuse>0.7 0.7 0.7 1</diffuse>
          <specular>0.01 0.01 0.01 1</specular>
          <emissive>0 0 0 1</emissive>
        </material>
        <transparency>0</transparency>
        <cast_shadows>1</cast_shadows>
      </visual>
      <collision name='collision'>
        <laser_retro>0</laser_retro>
        <max_contacts>10</max_contacts>
        <pose>0 0 0 0 -0 0</pose>
        <geometry>
          <mesh>
            <uri>/home/george/GEE301/Grabber stls/final stls/short_arm.stl</uri>
            <scale>1 1 1</scale>
          </mesh>
        </geometry>
        <surface>
          <friction>
            <ode>
              <mu>1</mu>
              <mu2>1</mu2>
              <fdir1>0 0 0</fdir1>
              <slip1>0</slip1>
              <slip2>0</slip2>
            </ode>
            <torsional>
              <coefficient>1</coefficient>
              <patch_radius>0</patch_radius>
              <surface_radius>0</surface_radius>
              <use_patch_radius>1</use_patch_radius>
              <ode>
                <slip>0</slip>
              </ode>
            </torsional>
          </friction>
          <bounce>
            <restitution_coefficient>0</restitution_coefficient>
            <threshold>1e+06</threshold>
          </bounce>
          <contact>
            <collide_without_contact>0</collide_without_contact>
            <collide_without_contact_bitmask>1</collide_without_contact_bitmask>
            <collide_bitmask>1</collide_bitmask>
            <ode>
              <soft_cfm>0</soft_cfm>
              <soft_erp>0.2</soft_erp>
              <kp>1e+13</kp>
              <kd>1</kd>
              <max_vel>0.01</max_vel>
              <min_depth>0</min_depth>
            </ode>
            <bullet>
              <split_impulse>1</split_impulse>
              <split_impulse_penetration_threshold>-0.01</split_impulse_penetration_threshold>
              <soft_cfm>0</soft_cfm>
              <soft_erp>0.2</soft_erp>
              <kp>1e+13</kp>
              <kd>1</kd>
            </bullet>
          </contact>
        </surface>
      </collision>
    </link>
    <joint name='link_0_JOINT_0' type='revolute'>
      <parent>link_0</parent>
      <child>link_1</child>
      <pose>0 0 0 0 -0 0</pose>
      <axis>
        <xyz>1 0 0</xyz>
        <limit>
          <lower>-1.79769e+308</lower>
          <upper>1.79769e+308</upper>
          <effort>-1</effort>
          <velocity>-1</velocity>
        </limit>
        <dynamics>
          <spring_reference>0</spring_reference>
          <spring_stiffness>0</spring_stiffness>
          <damping>0</damping>
          <friction>0</friction>
        </dynamics>
      </axis>
      <physics>
        <ode>
          <limit>
            <cfm>0</cfm>
            <erp>0.2</erp>
          </limit>
          <suspension>
            <cfm>0</cfm>
            <erp>0.2</erp>
          </suspension>
        </ode>
      </physics>
    </joint>
    <joint name='link_0_JOINT_11' type='revolute'>
      <parent>link_0</parent>
      <child>link_9</child>
      <pose>0 0 0 0 -0 0</pose>
      <axis>
        <xyz>1 0 0</xyz>
        <limit>
          <lower>-1.79769e+308</lower>
          <upper>1.79769e+308</upper>
          <effort>-1</effort>
          <velocity>-1</velocity>
        </limit>
        <dynamics>
          <spring_reference>0</spring_reference>
          <spring_stiffness>0</spring_stiffness>
          <damping>0</damping>
          <friction>0</friction>
        </dynamics>
      </axis>
      <physics>
        <ode>
          <limit>
            <cfm>0</cfm>
            <erp>0.2</erp>
          </limit>
          <suspension>
            <cfm>0</cfm>
            <erp>0.2</erp>
          </suspension>
        </ode>
      </physics>
    </joint>
    <joint name='link_0_JOINT_1' type='revolute'>
      <parent>link_0</parent>
      <child>link_2</child>
      <pose>0 0 0 0 -0 0</pose>
      <axis>
        <xyz>1 0 0</xyz>
        <limit>
          <lower>-1.79769e+308</lower>
          <upper>1.79769e+308</upper>
          <effort>-1</effort>
          <velocity>-1</velocity>
        </limit>
        <dynamics>
          <spring_reference>0</spring_reference>
          <spring_stiffness>0</spring_stiffness>
          <damping>0</damping>
          <friction>0</friction>
        </dynamics>
      </axis>
      <physics>
        <ode>
          <limit>
            <cfm>0</cfm>
            <erp>0.2</erp>
          </limit>
          <suspension>
            <cfm>0</cfm>
            <erp>0.2</erp>
          </suspension>
        </ode>
      </physics>
    </joint>
    <joint name='link_0_JOINT_5' type='revolute'>
      <parent>link_0</parent>
      <child>link_5</child>
      <pose>0 0 0 0 -0 0</pose>
      <axis>
        <xyz>1 0 0</xyz>
        <limit>
          <lower>-1.79769e+308</lower>
          <upper>1.79769e+308</upper>
          <effort>-1</effort>
          <velocity>-1</velocity>
        </limit>
        <dynamics>
          <spring_reference>0</spring_reference>
          <spring_stiffness>0</spring_stiffness>
          <damping>0</damping>
          <friction>0</friction>
        </dynamics>
      </axis>
      <physics>
        <ode>
          <limit>
            <cfm>0</cfm>
            <erp>0.2</erp>
          </limit>
          <suspension>
            <cfm>0</cfm>
            <erp>0.2</erp>
          </suspension>
        </ode>
      </physics>
    </joint>
    <joint name='link_0_JOINT_6' type='revolute'>
      <parent>link_0</parent>
      <child>link_6</child>
      <pose>0 0 0 0 -0 0</pose>
      <axis>
        <xyz>1 0 0</xyz>
        <limit>
          <lower>-1.79769e+308</lower>
          <upper>1.79769e+308</upper>
          <effort>-1</effort>
          <velocity>-1</velocity>
        </limit>
        <dynamics>
          <spring_reference>0</spring_reference>
          <spring_stiffness>0</spring_stiffness>
          <damping>0</damping>
          <friction>0</friction>
        </dynamics>
      </axis>
      <physics>
        <ode>
          <limit>
            <cfm>0</cfm>
            <erp>0.2</erp>
          </limit>
          <suspension>
            <cfm>0</cfm>
            <erp>0.2</erp>
          </suspension>
        </ode>
      </physics>
    </joint>
    <joint name='link_0_JOINT_9' type='revolute'>
      <parent>link_0</parent>
      <child>link_8</child>
      <pose>0 0 0 0 -0 0</pose>
      <axis>
        <xyz>1 0 0</xyz>
        <limit>
          <lower>-1.79769e+308</lower>
          <upper>1.79769e+308</upper>
          <effort>-1</effort>
          <velocity>-1</velocity>
        </limit>
        <dynamics>
          <spring_reference>0</spring_reference>
          <spring_stiffness>0</spring_stiffness>
          <damping>0</damping>
          <friction>0</friction>
        </dynamics>
      </axis>
      <physics>
        <ode>
          <limit>
            <cfm>0</cfm>
            <erp>0.2</erp>
          </limit>
          <suspension>
            <cfm>0</cfm>
            <erp>0.2</erp>
          </suspension>
        </ode>
      </physics>
    </joint>
    <joint name='link_1_JOINT_3' type='revolute'>
      <parent>link_1</parent>
      <child>link_3</child>
      <pose>0 0 0 0 -0 0</pose>
      <axis>
        <xyz>0 0 1</xyz>
        <limit>
          <lower>-1.79769e+308</lower>
          <upper>1.79769e+308</upper>
          <effort>-1</effort>
          <velocity>-1</velocity>
        </limit>
        <dynamics>
          <spring_reference>0</spring_reference>
          <spring_stiffness>0</spring_stiffness>
          <damping>0</damping>
          <friction>0</friction>
        </dynamics>
      </axis>
      <physics>
        <ode>
          <limit>
            <cfm>0</cfm>
            <erp>0.2</erp>
          </limit>
          <suspension>
            <cfm>0</cfm>
            <erp>0.2</erp>
          </suspension>
        </ode>
      </physics>
    </joint>
    <joint name='link_2_JOINT_4' type='revolute'>
      <parent>link_2</parent>
      <child>link_3</child>
      <pose>0.05 0 0 0 -0 0</pose>
      <axis>
        <xyz>0 0 1</xyz>
        <limit>
          <lower>-1.79769e+308</lower>
          <upper>1.79769e+308</upper>
          <effort>-1</effort>
          <velocity>-1</velocity>
        </limit>
        <dynamics>
          <spring_reference>0</spring_reference>
          <spring_stiffness>0</spring_stiffness>
          <damping>0</damping>
          <friction>0</friction>
        </dynamics>
      </axis>
      <physics>
        <ode>
          <limit>
            <cfm>0</cfm>
            <erp>0.2</erp>
          </limit>
          <suspension>
            <cfm>0</cfm>
            <erp>0.2</erp>
          </suspension>
        </ode>
      </physics>
    </joint>
    <joint name='link_3_0_JOINT_1' type='revolute'>
      <parent>link_1</parent>
      <child>link_3_0</child>
      <pose>0 0 0 0 -0 0</pose>
      <axis>
        <xyz>0 1 0</xyz>
        <limit>
          <lower>-1.79769e+308</lower>
          <upper>1.79769e+308</upper>
          <effort>-1</effort>
          <velocity>-1</velocity>
        </limit>
        <dynamics>
          <spring_reference>0</spring_reference>
          <spring_stiffness>0</spring_stiffness>
          <damping>0</damping>
          <friction>0</friction>
        </dynamics>
      </axis>
      <physics>
        <ode>
          <limit>
            <cfm>0</cfm>
            <erp>0.2</erp>
          </limit>
          <suspension>
            <cfm>0</cfm>
            <erp>0.2</erp>
          </suspension>
        </ode>
      </physics>
    </joint>
    <joint name='link_5_JOINT_7' type='revolute'>
      <parent>link_5</parent>
      <child>link_7</child>
      <pose>0 0 0 0 -0 0</pose>
      <axis>
        <xyz>0 0 1</xyz>
        <limit>
          <lower>-1.79769e+308</lower>
          <upper>1.79769e+308</upper>
          <effort>-1</effort>
          <velocity>-1</velocity>
        </limit>
        <dynamics>
          <spring_reference>0</spring_reference>
          <spring_stiffness>0</spring_stiffness>
          <damping>0</damping>
          <friction>0</friction>
        </dynamics>
      </axis>
      <physics>
        <ode>
          <limit>
            <cfm>0</cfm>
            <erp>0.2</erp>
          </limit>
          <suspension>
            <cfm>0</cfm>
            <erp>0.2</erp>
          </suspension>
        </ode>
      </physics>
    </joint>
    <joint name='link_6_JOINT_8' type='revolute'>
      <parent>link_6</parent>
      <child>link_7</child>
      <pose>0.05 0 0 0 -0 0</pose>
      <axis>
        <xyz>0 0 1</xyz>
        <limit>
          <lower>-1.79769e+308</lower>
          <upper>1.79769e+308</upper>
          <effort>-1</effort>
          <velocity>-1</velocity>
        </limit>
        <dynamics>
          <spring_reference>0</spring_reference>
          <spring_stiffness>0</spring_stiffness>
          <damping>0</damping>
          <friction>0</friction>
        </dynamics>
      </axis>
      <physics>
        <ode>
          <limit>
            <cfm>0</cfm>
            <erp>0.2</erp>
          </limit>
          <suspension>
            <cfm>0</cfm>
            <erp>0.2</erp>
          </suspension>
        </ode>
      </physics>
    </joint>
    <joint name='link_8_JOINT_12' type='revolute'>
      <parent>link_8</parent>
      <child>link_10</child>
      <pose>0 0 0 0 -0 0</pose>
      <axis>
        <xyz>0 0 1</xyz>
        <limit>
          <lower>-1.79769e+308</lower>
          <upper>1.79769e+308</upper>
          <effort>-1</effort>
          <velocity>-1</velocity>
        </limit>
        <dynamics>
          <spring_reference>0</spring_reference>
          <spring_stiffness>0</spring_stiffness>
          <damping>0</damping>
          <friction>0</friction>
        </dynamics>
      </axis>
      <physics>
        <ode>
          <limit>
            <cfm>0</cfm>
            <erp>0.2</erp>
          </limit>
          <suspension>
            <cfm>0</cfm>
            <erp>0.2</erp>
          </suspension>
        </ode>
      </physics>
    </joint>
    <joint name='link_9_JOINT_13' type='revolute'>
      <parent>link_9</parent>
      <child>link_10</child>
      <pose>0.05 0 0 0 -0 0</pose>
      <axis>
        <xyz>0 0 1</xyz>
        <limit>
          <lower>-1.79769e+308</lower>
          <upper>1.79769e+308</upper>
          <effort>-1</effort>
          <velocity>-1</velocity>
        </limit>
        <dynamics>
          <spring_reference>0</spring_reference>
          <spring_stiffness>0</spring_stiffness>
          <damping>0</damping>
          <friction>0</friction>
        </dynamics>
      </axis>
      <physics>
        <ode>
          <limit>
            <cfm>0</cfm>
            <erp>0.2</erp>
          </limit>
          <suspension>
            <cfm>0</cfm>
            <erp>0.2</erp>
          </suspension>
        </ode>
      </physics>
    </joint>
    <static>0</static>
    <allow_auto_disable>1</allow_auto_disable>
  </model>
</sdf>
